Workbook

Sheet MANIFEST
A1: Sample Label | B1: Description | C1: Thickness | D1: Slide or Tube | E1: Group | F1: GFP | G1: Type | H1: Animal | I1: Location | J1: Used | K1: Details | L1: Notes | M1: NI | N1: Raman | O1: SHG | P1: SAXS | Q1: labSAXS | R1: Microscopy | S1: demo/practice
A2: 1 Paper | B2: 60um block 1 Female adult back skin 1 10 weeks 10um, 30um 60um | C2: 60 | D2: Slide | E2: Plain | G2: Plain | H2: Mouse | I2: RAMAN BOX | J2: Yes | K2: cover slip | L2: For paper | M2: done | N2: done
A3: 2 Paper | B3: 60um block 1 Female adult back skin 1 10 weeks 10um, 30um 60um | C3: 60 | D3: Slide | E3: Plain | G3: Plain | H3: Mouse | I3: SHG BOX | J3: Yes | K3: fixed | L3: For paper | O3: to do
A4: 3 Paper | B4: 60um block 1 Female adult back skin 1 10 weeks 10um, 30um 60um | C4: 60 | D4: Slide | E4: Plain | G4: Plain | H4: Mouse | I4: DONE BOX | J4: Yes | L4: For paper
A5: 4 Paper | B5: 60um block 1 Female adult back skin 1 10 weeks 10um, 30um 60um | C5: 60 | D5: Slide | E5: Plain | G5: Plain | H5: Mouse | I5: DONE BOX | J5: Yes | L5: For paper | M5: done | O5: to do
A6: 5 Paper | B6: 60um block 1 Female adult back skin 1 10 weeks 10um, 30um 60um | C6: 60 | D6: Slide | E6: Plain | G6: Plain | H6: Mouse | I6: SHG BOX | J6: Yes | K6: fixed | L6: For paper
A7: 6 Paper | B7: 60um block 1 Female adult back skin 1 10 weeks 10um, 30um 60um | C7: 60 | D7: Slide | E7: Plain | G7: Plain | H7: Mouse | I7: RAMAN BOX | J7: Yes | K7: cover slip | L7: For paper | M7: done | N7: to do
A8: 7 Paper | B8: 30um block 1 Female adult back skin 1 10 weeks 10um, 30um 60um | C8: 30 | D8: Slide | E8: Plain | G8: Plain | H8: Mouse | I8: PAPER BOX | L8: For paper
A9: 8 Paper | B9: 30um block 1 Female adult back skin 1 10 weeks 10um, 30um 60um | C9: 30 | D9: Slide | E9: Plain | G9: Plain | H9: Mouse | I9: DONE BOX | J9: Yes | L9: For paper | M9: done
A10: 9 Paper | B10: 30um block 1 Female adult back skin 1 10 weeks 10um, 30um 60um | C10: 30 | D10: Slide | E10: Plain | G10: Plain | H10: Mouse | I10: PAPER BOX | L10: For paper
A11: 10 Paper | B11: 30um block 1 Female adult back skin 1 10 weeks 10um, 30um 60um | C11: 30 | D11: Slide | E11: Plain | G11: Plain | H11: Mouse | I11: PAPER BOX | L11: For paper
A12: 11 Paper | B12: 10um block 1 Female adult back skin 1 10 weeks 10um, 30um 60um | C12: 12 | D12: Slide | E12: Plain | G12: Plain | H12: Mouse | I12: SHG BOX | J12: used | L12: For paper | R12: done
A13: 12 Paper | B13: 10um block 1 Female adult back skin 1 10 weeks 10um, 30um 60um | C13: 12 | D13: Slide | E13: Plain | G13: Plain | H13: Mouse | I13: PAPER BOX | J13: Yes | L13: For paper | M13: done
A14: 13 Paper | B14: 10um block 1 Female adult back skin 1 10 weeks 10um, 30um 60um | C14: 12 | D14: Slide | E14: Plain | G14: Plain | H14: Mouse | I14: SHG BOX | J14: used | L14: For paper | R14: done
A15: 14 Paper | B15: 10um block 1 Female adult back skin 1 10 weeks 10um, 30um 60um | C15: 12 | D15: Slide | E15: Plain | G15: Plain | H15: Mouse | I15: SHG BOX | J15: used | L15: For paper | R15: done
A16: 15 Paper | B16: 60um block 2 GFP adult female back skin 2 NF WT | C16: 60 | D16: Slide | E16: Plain | F16: GFP | G16: Plain | H16: Mouse | I16: DONE BOX | J16: Yes | L16: For paper
A17: 16 Paper | B17: 60um block 2 GFP adult female back skin 2 NF WT | C17: 60 | D17: Slide | E17: Plain | F17: GFP | G17: Plain | H17: Mouse | I17: DONE BOX | J17: Yes | L17: For paper
A18: 17 Paper | B18: 60um block 2 GFP adult female back skin 2 NF WT | C18: 60 | D18: Slide | E18: Plain | F18: GFP | G18: Plain | H18: Mouse | I18: RAMAN BOX | J18: Yes | K18: cover slip | L18: For paper | N18: to do
A19: 18 Paper | B19: 60um block 2 GFP adult female back skin 2 NF WT | C19: 60 | D19: Slide | E19: Plain | F19: GFP | G19: Plain | H19: Mouse | I19: DONE BOX | J19: Yes | L19: For paper | M19: done
A20: 19 Paper | B20: 60um block 2 GFP adult female back skin 2 NF WT | C20: 60 | D20: Slide | E20: Plain | F20: GFP | G20: Plain | H20: Mouse | I20: BIN | L20: For paper
A21: 20 Paper | B21: 60um block 2 GFP adult female back skin 2 NF WT | C21: 60 | D21: Slide | E21: Plain | F21: GFP | G21: Plain | H21: Mouse | I21: DONE BOX | J21: Yes | L21: For paper | M21: done
A22: 21 Paper | B22: 30um block 2 GFP adult female back skin 2 NF WT | C22: 30 | D22: Slide | E22: Plain | F22: GFP | G22: Plain | H22: Mouse | I22: SHG BOX | J22: Yes | K22: fixed | L22: For paper | O22: to do
A23: 22 Paper | B23: 30um block 2 GFP adult female back skin 2 NF WT | C23: 30 | D23: Slide | E23: Plain | F23: GFP | G23: Plain | H23: Mouse | I23: SHG BOX | J23: Yes | K23: fixed | L23: For paper | M23: done | O23: to do
A24: 23 Paper | B24: 30um block 2 GFP adult female back skin 2 NF WT | C24: 30 | D24: Slide | E24: Plain | F24: GFP | G24: Plain | H24: Mouse | I24: PAPER BOX | L24: For paper
A25: 24 Paper | B25: 30um block 2 GFP adult female back skin 2 NF WT | C25: 30 | D25: Slide | E25: Plain | F25: GFP | G25: Plain | H25: Mouse | I25: PAPER BOX | L25: For paper
A26: 25 Paper | B26: 12um block 2 GFP adult female back skin 2 NF WT | C26: 12 | D26: Slide | E26: Plain | F26: GFP | G26: Plain | H26: Mouse | I26: SHG BOX | J26: Yes | K26: fixed | L26: For paper | O26: to do | R26: to do
A27: 26 Paper | B27: 12um block 2 GFP adult female back skin 2 NF WT | C27: 12 | D27: Slide | E27: Plain | F27: GFP | G27: Plain | H27: Mouse | J27: Yes | K27: fixed | L27: For paper | O27: to do
A28: 27 Paper | B28: 12um block 2 GFP adult female back skin 2 NF WT | C28: 12 | D28: Slide | E28: Plain | F28: GFP | G28: Plain | H28: Mouse | I28: SHG BOX | J28: used | L28: For paper | R28: done
A29: 28 Paper | B29: 12um block 2 GFP adult female back skin 2 NF WT | C29: 12 | D29: Slide | E29: Plain | F29: GFP | G29: Plain | H29: Mouse | I29: SHG BOX | J29: Yes | K29: fixed | L29: For paper | M29: done | O29: to do
A30: 29 Paper | B30: 60um block 3 W day 10 (no wound) female 07/10/22 | C30: 60 | D30: Slide | E30: Plain | G30: Plain | H30: Mouse | I30: PAPER BOX | L30: For paper
A31: 30 Paper | B31: 60um block 3 W day 10 (no wound) female 07/10/22 | C31: 60 | D31: Slide | E31: Plain | G31: Plain | H31: Mouse | I31: RAMAN BOX | J31: Yes | K31: cover sip | L31: For paper | M31: done | N31: done
A32: 31 Paper | B32: 60um block 3 W day 10 (no wound) female 07/10/22 | C32: 60 | D32: Slide | E32: Plain | G32: Plain | H32: Mouse | I32: SHG BOX | K32: fixed | L32: For paper | O32: to do
A33: 32 Paper | B33: 60um block 3 W day 10 (no wound) female 07/10/22 | C33: 60 | D33: Slide | E33: Plain | G33: Plain | H33: Mouse | I33: RAMAN BOX | J33: Yes | K33: cover slip | L33: For paper | M33: done | N33: done
A34: 33 Paper | B34: 60um block 3 W day 10 (no wound) female 07/10/22 | C34: 60 | D34: Slide | E34: Plain | G34: Plain | H34: Mouse | I34: SHG BOX | J34: Yes | K34: fixed | L34: For paper
A35: 34 Paper | B35: 60um block 3 W day 10 (no wound) female 07/10/22 | C35: 60 | D35: Slide | E35: Plain | G35: Plain | H35: Mouse | I35: PAPER BOX | L35: For paper
A36: 35 Paper | B36: 30um block 3 W day 10 (no wound) female 07/10/22 | C36: 30 | D36: Slide | E36: Plain | G36: Plain | H36: Mouse | I36: PAPER BOX | L36: For paper
A37: 36 Paper | B37: 30um block 3 W day 10 (no wound) female 07/10/22 | C37: 30 | D37: Slide | E37: Plain | G37: Plain | H37: Mouse | I37: SHG BOX | J37: Yes | K37: fixed | L37: For paper | M37: done | O37: to do
A38: 37 Paper | B38: 30um block 3 W day 10 (no wound) female 07/10/22 | C38: 30 | D38: Slide | E38: Plain | G38: Plain | H38: Mouse | I38: PAPER BOX | L38: For paper
A39: 38 Paper | B39: 30um block 3 W day 10 (no wound) female 07/10/22 | C39: 30 | D39: Slide | E39: Plain | G39: Plain | H39: Mouse | I39: PAPER BOX | L39: For paper
A40: 39 Paper | B40: 12um block 3 W day 10 (no wound) female 07/10/22 | C40: 12 | D40: Slide | E40: Plain | G40: Plain | H40: Mouse | I40: DONE BOX | J40: Yes | L40: For paper | R40: to do
...

Sheet Lab book NI
A1: Sample | B1: Type | C1: Group | D1: Sample Name | E1: Date | F1: Time | G1: thickness | H1: Notes | I1: depth | J1: speed | K1: hold | L1: Res | M1: Region | N1: Scan | O1: File name | P1: Notes | Q1: Image name
A2: 270 | B2: VEH | C2: AP1 | D2: Vehicle ap1 1P 10/03/23 (1) | E2: 13/08/24 | F2: 0.66666667 | G2: 12 | H2: label edge | I2: 1200 | J2: 2500 | K2: 3 | L2: 10
A3: 269 | B3: TS | C3: AP1 | D3: T5224 F1-1 18/8/23 | E3: 13/08/24 | F3: 0.41666667 | G3: 12 | H3: label edge | I3: 1200 | J3: 2500 | K3: 3 | L3: 10
A4: 275 | B4: VEH | C4: AP1 | D4: Vehicle ap1 F1-1 18/8/23 | E4: 13/08/24 | F4: 0.70833333 | G4: 12 | H4: label edge | I4: 1200 | J4: 2500 | K4: 3 | L4: 10
A5: 277 | B5: VEH | C5: AP1 | D5: Vehicle ap1 F2-1 18/8/23 | E5: 13/08/24 | F5: 0.58333333 | G5: 12 | H5: label edge | I5: 1200 | J5: 2500 | K5: 3 | L5: 10
A6: 274 (mislab 271) | B6: TS | C6: AP1 | D6: T5224 F2-2 18/8/23 | E6: 13/08/24 | F6: 0.45833333 | G6: 12 | H6: label edge | I6: 1200 | J6: 2500 | K6: 3 | L6: 10 | P6: was at one point mislabelled 271A
A7: 272 | B7: TS | C7: AP1 | D7: T5224 F3-2 18/8/23 | E7: 13/08/24 | F7: 0.54166667 | G7: 12 | H7: label edge | I7: 1200 | J7: 2500 | K7: 3 | L7: 10
A8: 278 | B8: CL | C8: CL | D8: pw21 F1-1 16/7/24 (7) CL | E8: 23/08/24 | F8: 0.54166667 | G8: 12 | H8: label edge | I8: 1200 | J8: 2500 | K8: 3 | L8: 10
A9: 279 | B9: ACE | C9: CL | D9: pw21 F1-2 16/7/24 (2) CL ace | E9: 45331 | F9: 0.54166667 | G9: 12 | H9: label edge | I9: 1200 | J9: 2500 | K9: 3 | L9: 10
A10: 284 | B10: CL | C10: CL | D10: pw21 M1-2 16/7/24 CL | E10: 45331 | F10: 0.45833333 | G10: 12 | H10: label edge | I10: 1200 | J10: 2500 | K10: 3 | L10: 10
A11: 285 | B11: CL | C11: CL | D11: pw21 M2-1 16/7/24 (5) CL | E11: 23/08/24 | F11: 0.625 | G11: 12 | H11: label edge | I11: 1200 | J11: 2500 | K11: 3 | L11: 10
A12: 16F (f21 ts) | B12: TS | C12: AP1 | D12: T5224 sample F2-1 Female 2 Wound 1 10days PW 18/8/23 | E12: 14/03/24 | F12: 0.70833333 | G12: 12 | H12: label edge | I12: 1200 | J12: 2500 | K12: 3 | L12: 10
A13: 19g (f32 ts) | B13: TS | C13: AP1 | D13: T5224 sample F3-2 Female 3 Wound 2 10days PW 18/8/23 | E13: 45632 | F13: 0.375 | G13: 12 | H13: label edge | I13: 1200 | J13: 2500 | K13: 3 | L13: 10
A14: 23H (veh f22) | B14: VEH | C14: AP1 | D14: Vehicle control Female 2 Wound 2 10days PW 18/8/23 | E14: 21/03/24 | F14: 0.66666667 | G14: 12 | H14: label edge | I14: 1200 | J14: 2500 | K14: 3 | L14: 10
A15: 20H (veh t11) | B15: VEH | C15: AP1 | D15: Vehicle control F1-1 Female 1 Wound 1 10days PW 18/8/2 | E15: 14/03/24 | F15: 0.66666667 | G15: 12 | H15: label edge | I15: 1200 | J15: 2500 | K15: 3 | L15: 10
A16: 1 | B16: Plain 60 | C16: PLAIN | D16: 60um block 1 Female adult back skin 1 10 weeks 10um, 30um 60um | E16: 44996 | F16: 0.45833333 | G16: 60 | I16: 5000 | J16: 2500 | K16: 3 | L16: 10
A17: 6 | B17: Plain 60 | C17: PLAIN | D17: 60um block 1 Female adult back skin 1 10 weeks 10um, 30um 60um | E17: 22/11/23 | F17: 0.45833333 | G17: 60 | I17: 5000 | J17: 2500 | K17: 3 | L17: 10
A18: 18 | B18: Plain 60 | C18: PLAIN | D18: 60um block 2 GFP adult female back skin 2 NF WT | E18: 45505 | F18: 0.5 | G18: 60 | I18: 5000 | J18: 2500 | K18: 3 | L18: 10
A19: 30 | B19: Plain 60 | C19: PLAIN | D19: 60um block 3 W day 10 (no wound) female 07/10/22 | E19: 45505 | F19: 0.54166667 | G19: 60 | I19: 5000 | J19: 2500 | K19: 3 | L19: 10
A20: 44 | B20: Plain 60 | C20: PLAIN | D20: 60um block 4 WT back skin wound day 2 (no wound) WT3 female | E20: 45566 | F20: 0.45833333 | G20: 60 | I20: 5000 | J20: 2500 | K20: 3 | L20: 10
A21: 5 | B21: Plain 60 | C21: PLAIN | D21: 60um block 1 Female adult back skin 1 10 weeks 10um, 30um 60um | E21: 16/02/24 | F21: 0.66666667 | G21: 60 | I21: 5000 | J21: 2500 | K21: 3 | L21: 10
A22: 4 | B22: Plain 60 | C22: PLAIN | D22: 60um block 1 Female adult back skin 1 10 weeks 10um, 30um 60um | E22: 29/01/24 | F22: 0.41666667 | G22: 60 | I22: 5000 | J22: 2500 | K22: 3 | L22: 10
A23: 20 | B23: Plain 60 | C23: PLAIN | D23: 60um block 2 GFP adult female back skin 2 NF WT | E23: 23/01/24 | F23: 0.5 | G23: 60 | I23: 5000 | J23: 2500 | K23: 3 | L23: 10
A24: 32 | B24: Plain 60 | C24: PLAIN | D24: 60um block 3 W day 10 (no wound) female 07/10/22 | E24: 22/01/24 | F24: 0.5 | G24: 60 | I24: 5000 | J24: 2500 | K24: 3 | L24: 10
A25: 45 | B25: Plain 60 | C25: PLAIN | D25: 60um block 4 WT back skin wound day 2 (no wound) WT3 female | E25: 17/01/24 | F25: 0.625 | G25: 60 | I25: 5000 | J25: 2500 | K25: 3 | L25: 10
A26: 8 | B26: Plain 30 | C26: PLAIN | D26: 30um block 1 Female adult back skin 1 10 weeks 10um, 30um 60um | E26: 22/11/23 | F26: 0.5 | G26: 30 | I26: 2500 | J26: 1250 | K26: 3 | L26: 10
A27: 36 | B27: Plain 30 | C27: PLAIN | D27: 30um block 3 W day 10 (no wound) female 07/10/22 | E27: 45566 | F27: 0.5 | G27: 30 | I27: 2500 | J27: 1250 | K27: 3 | L27: 10
A28: 22 | B28: Plain 30 | C28: PLAIN | D28: 30um block 2 GFP adult female back skin 2 NF WT | E28: 45566 | F28: 0.54166667 | G28: 30 | I28: 2500 | J28: 1250 | K28: 3 | L28: 10
A29: 51 | B29: Plain 30 | C29: PLAIN | D29: 30um block 4 WT back skin wound day 2 (no wound) WT3 female | E29: 45566 | F29: 0.58333333 | G29: 30 | I29: 2500 | J29: 1250 | K29: 3 | L29: 10
A30: 28 | B30: Plain 12 | C30: PLAIN | D30: 12um block 2 GFP adult female back skin 2 NF WT | E30: 16/01/24 | F30: 0.52083333 | G30: 12 | I30: 1250 | J30: =1250/2 -> 625 | K30: 3 | L30: 10
A31: 12 | B31: Plain 12 | C31: PLAIN | D31: 10um block 1 Female adult back skin 1 10 weeks 10um, 30um 60um | E31: 22/11/23 | F31: 0.5 | G31: 12 | I31: 1250 | J31: =1250/2 -> 625 | K31: 3 | L31: 10
A32: 41 | B32: Plain 12 | C32: PLAIN | D32: 12um block 3 W day 10 (no wound) female 07/10/22 | E32: 16/01/24 | F32: 0.54166667 | G32: 12 | I32: 1250 | J32: =1250/2 -> 625 | K32: 3 | L32: 10
A33: 53 | B33: Plain 12 | C33: PLAIN | D33: 12um block 4 WT back skin wound day 2 (no wound) WT3 female | E33: 16/01/24 | F33: 0.58333333 | G33: 12 | I33: 1250 | J33: =1250/2 -> 625 | K33: 3 | L33: 10
A34: 54 | B34: Plain 12 | C34: PLAIN | D34: 12um block 4 WT back skin wound day 2 (no wound) WT3 female | E34: 16/01/24 | F34: 0.625 | G34: 12 | I34: 1250 | J34: =1250/2 -> 625 | K34: 3 | L34: 10
A35: 156 | B35: D14 | C35: WOUNDING | D35: Wound NF (1) adult GFP PW14 male 22.07.2022 | E35: 13/02/24 | F35: 0.58333333 | G35: 60 | I35: 5000 | J35: 2500 | K35: 3 | L35: 10
A36: 166 | B36: D14 | C36: WOUNDING | D36: Wound NF (2) adult GF7 PW14 male 22.07.2022 | E36: 29/05/24 | F36: 0.375 | G36: 60 | I36: 5000 | J36: 2500 | K36: 3 | L36: 10
A37: 201 | B37: VEH | C37: AP1 | D37: Vehicle control sample F2-1 Female 2 Wound 1 10days PW 18/08/23 (same as 303) | E37: 29/05/24 | F37: 0.45833333 | G37: 12 | H37: too deep for sample | I37: 5000 | J37: 2500 | K37: 3 | L37: 10
A38: 210 | B38: D10 | C38: WOUNDING | D38: (2) NF GFP PW10 female 07.10.22 | E38: 20/06/24 | F38: 0.5 | G38: 60 | I38: 5000 | J38: 2500 | K38: 3 | L38: 10
A39: 212 | B39: D10 | C39: WOUNDING | D39: (3) NF GFP PW10 Female 07.10.22 | E39: 20/06/24 | F39: 0.54166667 | G39: 60 | I39: 5000 | J39: 2500 | K39: 3 | L39: 10
A40: 215 | B40: D10 | C40: WOUNDING | D40: (4) NF GFP PW10 Female 07.10.22 | E40: 25/06/24 | F40: 0.41666667 | G40: 60 | I40: 5000 | J40: 2500 | K40: 3 | L40: 10
...

Sheet Lab book Raman
A1: Date | B1: Time | C1: Sample Number | D1: Type | E1: Thickness | F1: Sample Name | G1: Focused on | H1: Sample focus position (z) | I1: exposure time | J1: power | K1: accumulations | L1: Laser | M1: pinhole | N1: Objective | O1: Scan Type | P1: Res (x by y) | Q1: Image Name | R1: End z (Depth scan) | S1: Start z (Depth scan) | T1: Step Size (um) | U1: Number Points | V1: Time Taken | W1: Wavenumber Start | X1: Wavenumber Centre | Y1: Wavenumber End | Z1: File Name | AA1: Notes
A2: 16/10/24 | B2: 0.58333333 | C2: 34 | D2: Plain 60 | E2: 60 | F2: 60um block 3 W day 10 (no wound) female 07/10/22 | I2: 1s | J2: 1 | K2: 10 | L2: 442 | M2: OUT | N2: 20 | O2: Grid Scan | P2: 100x10 | AA2: coverslipped sample, grid scan of 2x81 pts for baseline sample
A3: 16/10/24 | B3: 0.625 | C3: 31 | D3: fixed 60um sample | E3: 60 | F3: 60um block 3 W day 10 (no wound) female 07/10/22 | I3: 1s | J3: 1 | K3: 10 | L3: 442 | M3: OUT | N3: 20 | O3: Grid Scan | P3: 100x10 | AA3: coverslipped sample, grid scan of 2x81 pts for baseline sample
A4: 16/10/24 | B4: 0.66666667 | C4: 35 | D4: Plain 30um | E4: 30 | F4: 30um block 3 W day 10 (no wound) female 07/10/22 | I4: 1s | J4: 1 | K4: 10 | L4: 442 | M4: OUT | N4: 20 | O4: Grid Scan | P4: 100x10 | AA4: no image taken, need to redo. coverslipped sample, grid scan of 2x81 pts for baseline sample
A5: 23/20/24 | B5: 0.58333333 | C5: 34 | D5: Plain 60 | E5: 60 | F5: 60um block 3 W day 10 (no wound) female 07/10/22 | I5: 1s | J5: 1 | K5: 10 | L5: 442 | M5: OUT | N5: 20 | O5: Depth Scan | Z5: GL_GL Depth Low Range (Sample) | AA5: -498um to 400um (depth scan within dermal tissue), 2um steps
A6: 23/20/24 | B6: 0.58333333 | C6: 34 | D6: Plain 60 | E6: 60 | F6: 60um block 3 W day 10 (no wound) female 07/10/22 | I6: 1s | J6: 1 | K6: 10 | L6: 442 | M6: OUT | N6: 20 | O6: Damage Test | AA6: damage scan (20 repeats at same point within dermal tissue)
A7: 23/20/24 | B7: 0.625 | C7: 34 | D7: Plain 60 | E7: 60 | F7: 60um block 3 W day 10 (no wound) female 07/10/22 | I7: 1s | J7: 1 | K7: 10 | L7: 442 | M7: OUT | N7: 20 | O7: Single Aq | Z7: GL_GL SingAq Low Range (Sample) | AA7: single point - single acquisition in dermal tissue
A8: 23/20/24 | B8: 0.625 | C8: 34 | D8: Plain 60 | E8: 60 | F8: 60um block 3 W day 10 (no wound) female 07/10/22 | I8: 1s | J8: 1 | K8: 10 | L8: 442 | M8: OUT | N8: 20 | O8: Depth Scan | Z8: GL_GL Depth Low Range (NONE) 1 | AA8: depth scan -498 to 400um 5um steps in glass region only
A9: 30/10/24 | B9: 0.45833333 | C9: 34 | D9: Plain 60 | E9: 60 | F9: 60um block 3 W day 10 (no wound) female 07/10/22 | I9: 1s | J9: 1 | K9: 10 | L9: 442 | M9: IN | N9: 20 | O9: Depth Scan | Z9: GL_GL Depth Low Range (NONE) 2 | AA9: depth scan 4um steps in glass region only (pinhole in) (low range)
A10: 30/10/24 | B10: 0.47916667 | C10: 34 | D10: Plain 60 | E10: 60 | F10: 60um block 3 W day 10 (no wound) female 07/10/22 | I10: 1s | J10: 1 | K10: 10 | L10: 442 | M10: IN | N10: 20 | O10: Depth Scan | Z10: UL_GL Depth Low Range (sample) | AA10: UL and glass depth scan 4um steps in sample region (pinhole in) (low range)
A11: 30/10/24 | B11: 0.48958333 | C11: 34 | D11: Plain 60 | E11: 60 | F11: 60um block 3 W day 10 (no wound) female 07/10/22 | G11: Sample | I11: 1s | J11: 1 | K11: 3 | L11: 442 | M11: IN | N11: 20 | O11: Depth Scan | Z11: UL_GL Depth High Range (sample) | AA11: UL and glass depth scan 4um steps in sample region (pinhole in) (high range)
A12: 45454 | B12: 0.4375 | C12: 17F | D12: TS sample | E12: 12 | F12: T5224 sample F2-2 Female 2 Wound 2 10days PW 18/8/23 | G12: Sample | H12: 2084 | I12: 1s | J12: 1 | K12: 3 | L12: 442 | M12: IN | N12: 20 | O12: Depth Scan | Q12: image_1993z_glassviewupper_glassglass // image_2084z_sampleview_glassglass //i mage_2210z_glassviewlower_glassglass | R12: 1993 | S12: 2210 | T12: 2 | U12: 110 | V12: 16 min | W12: 621 | X12: 1600 | Y12: 2436 | Z12: GL_GL_Depth Low Range (sample) 2 | AA12: Glass and glass cover slip, z scan (focused on sample)
A13: 45454 | B13: 0.44791667 | C13: 17F | D13: TS sample | E13: 12 | F13: T5224 sample F2-2 Female 2 Wound 2 10days PW 18/8/23 | G13: Glass | H13: 2100 | I13: 1s | J13: 1 | K13: 3 | L13: 442 | M13: IN | N13: 20 | O13: Depth Scan | Q13: image_2100z_sampleview_glassglass (no sample) | R13: 1992 | S13: 2210 | T13: 2 | U13: 110 | V13: 16 min | W13: 621 | X13: 1600 | Y13: 2436 | Z13: GL_GL_Depth Low Range (none) 3 | AA13: Glass and glass cover slip, z scan (focused on nothing)
A14: 45454 | B14: 0.45833333 | C14: 17F | D14: TS sample | E14: 12 | F14: T5224 sample F2-2 Female 2 Wound 2 10days PW 18/8/23 | G14: Sample | H14: 2029 | I14: 1s | J14: 1 | K14: 3 | L14: 442 | M14: IN | N14: 20 | O14: Depth Scan | Q14: image_2029z_glassviewupper_glassul // image_2029z_sampleview_glassUL // image_2237z_glassviewlower_glassul | R14: 1972 | S14: 2230 | T14: 2 | U14: 130 | V14: 19 min | W14: 621 | X14: 1600 | Y14: 2436 | Z14: GL_UL_Depth low range (sample) 2 | AA14: Glass and Ultralene, z scan (focused on sample)
A15: 45454 | B15: 0.47916667 | C15: 17F | D15: TS sample | E15: 12 | F15: T5224 sample F2-2 Female 2 Wound 2 10days PW 18/8/23 | G15: Glass | H15: 2148 | I15: 1s | J15: 1 | K15: 3 | L15: 442 | M15: IN | N15: 20 | O15: Depth Scan | Q15: image_2148z_sampleview_glassul (no sample) | R15: 1972 | S15: 2230 | T15: 2 | U15: 130 | V15: 19 min | W15: 621 | X15: 1600 | Y15: 2436 | Z15: GL_UL_Depth low range (none) 2 | AA15: Glass and ultralene, z scan (focused on nothing)
A16: 45454 | B16: 0.5 | C16: 17F | D16: TS sample | E16: 12 | F16: T5224 sample F2-2 Female 2 Wound 2 10days PW 18/8/23 | G16: Glass | H16: 2154 | I16: 1s | J16: 1 | K16: 3 | L16: 442 | M16: IN | N16: 50 | O16: Depth Scan | Q16: image_2154z_sampleview_glassglass (sample) 50 obj | R16: 2108 | S16: 2202 | T16: 2 | U16: 48 | V16: 7 min | W16: 621 | X16: 1600 | Y16: 2436 | Z16: GL_GL_Depth low range (sample) 50obj | AA16: Glass and glass cover slip, z scan (focused on sample) x50 obj
A17: 45454 | B17: 0.4375 | C17: 17F | D17: TS sample | E17: 12 | F17: T5224 sample F2-2 Female 2 Wound 2 10days PW 18/8/23 | G17: Sample | H17: unknown | I17: 1s | J17: 1 | K17: 3 | L17: 442 | M17: IN | N17: 20 | O17: Depth Scan | R17: 1980 | S17: 2220 | T17: 2 | U17: 120 | V17: 18min | W17: 621 | X17: 1600 | Y17: 2436 | Z17: GL_UL_Depth Low Range (none) 4 no pbs no sample | AA17: Glass and ultralene, z scan (focused on nothing)
A18: 28/11/2024 | B18: 0.4375 | C18: 128 | D18: Plain | E18: 500 | F18: B2 – Bleo 4R - PBSMET (4) | H18: unknown | I18: 1s | J18: 1 | K18: 4 | L18: 442 | M18: IN | N18: 20 | O18: Depth Scan | R18: -795 | S18: -48 | T18: 3 | V18: 20min | W18: 621 | X18: 1600 | Y18: 2436 | Z18: Depthscan_ULUL
A19: 28/11/2024 | B19: 0.4375 | C19: 128 | D19: Plain | E19: 500 | F19: B2 – Bleo 4R - PBSMET (4) | I19: 1s | J19: 1 | K19: 4 | L19: 442 | M19: IN | N19: 20 | O19: Depth Scan | R19: -795 | S19: -48 | T19: 3 | V19: 20min | W19: 621 | X19: 1600 | Y19: 2436 | Z19: Depthscan_ULUL2
A20: 28/11/2024 | B20: 0.4375 | C20: 171 | D20: Plain | E20: 500 | F20: B2– Bleo 2 – PBS (2) | I20: 1s | J20: 1 | K20: 4 | L20: 442 | M20: IN | N20: 20 | O20: Depth Scan | R20: -795 | S20: -48 | T20: 3 | V20: 20min | W20: 621 | X20: 1600 | Y20: 2436 | Z20: Depthscan_ULUL3
A21: 28/11/2024 | B21: 0.4375 | C21: 171 | D21: Plain | E21: 500 | F21: B2– Bleo 2 – PBS (2) | I21: 1s | J21: 1 | K21: 4 | L21: 442 | M21: IN | N21: 20 | O21: Depth Scan | R21: -1800 | S21: -606 | T21: 6 | U21: 200 | V21: 30 | W21: 621 | X21: 1600 | Y21: 2436 | Z21: Depthscan_kapton
A22: 28/11/2024 | B22: 0.4375 | C22: 171 | D22: Plain | E22: 500 | F22: B2– Bleo 2 – PBS (2) | I22: 1s | J22: 1 | K22: 4 | L22: 442 | M22: IN | N22: 20 | O22: Depth Scan | R22: -1800 | S22: -606 | T22: 6 | U22: 200 | V22: 30 | W22: 621 | X22: 1600 | Y22: 2436 | Z22: Depthscan_kapton2
A23: 17/12/24 | B23: 0.38888889 | C23: 263 | D23: Plain | E23: 60 | F23: (B) laser sample lower incision (8) | G23: Sample (?) | H23: -2000 | I23: 1s | J23: 1 | K23: 4 | L23: 442 | M23: IN | N23: 20 | O23: Depth Scan | R23: -1779 | S23: -2335 | T23: 4 | U23: 140 | V23: 21min | W23: 621 | X23: 1600 | Y23: 2436 | AA23: Ultralene-sample-ultralene
A24: 17/12/24 | B24: 0.39583333 | C24: 263 | D24: Plain | E24: 60 | F24: (B) laser sample lower incision (8) | G24: Sample (?) | H24: -2000 | I24: 1s | J24: 1 | K24: 4 | L24: 442 | M24: IN | N24: 20 | O24: Depth Scan | R24: -1779 | S24: -2335 | T24: 4 | U24: 140 | V24: 21min | W24: 621 | X24: 1600 | Y24: 2436 | AA24: Ultralene-sample-ultralene
A25: 17/12/24 | B25: 0.39930556 | C25: 263 | D25: Plain | E25: 60 | F25: (B) laser sample lower incision (8) | G25: Nothing | I25: 1s | J25: 1 | K25: 4 | L25: 442 | M25: IN | N25: 20 | O25: Depth Scan | R25: -1779 | S25: -2335 | T25: 4 | U25: 140 | V25: 21min | W25: 621 | X25: 1600 | Y25: 2436 | AA25: Ultralene-blank-ultralene
A26: 17/12/24 | B26: 0.40625 | C26: 125 | D26: Plain | E26: 500 | F26: B1 - Bleo 3R - 2w | G26: Sample (?) | I26: 1s | J26: 1 | K26: 4 | L26: 442 | M26: IN | N26: 20 | O26: Depth Scan | R26: -3068 | S26: -2600 | T26: 4 | U26: 140 | V26: 21min | W26: 621 | X26: 1600 | Y26: 2436 | AA26: kapton-sample-kapton
A27: 17/12/24 | B27: 0.41666667 | C27: 125 | D27: Plain | E27: 500 | F27: B1 - Bleo 3R - 2w | G27: Sample (?) | I27: 1s | J27: 1 | K27: 4 | L27: 442 | M27: IN | N27: 20 | O27: Depth Scan | R27: -3068 | S27: -2600 | T27: 4 | U27: 140 | V27: 21min | W27: 621 | X27: 1600 | Y27: 2436 | AA27: kapton-sample-kapton
A28: 17/12/24 | B28: 0.43402778 | C28: 125 | D28: Plain | E28: 500 | F28: B1 - Bleo 3R - 2w | G28: Nothing | I28: 1s | J28: 1 | K28: 4 | L28: 442 | M28: IN | N28: 20 | O28: Depth Scan | R28: -3068 | S28: -2600 | T28: 4 | U28: 140 | V28: 21min | W28: 621 | X28: 1600 | Y28: 2436 | AA28: kapton-blank-kapton
A29: 17/12/24 | B29: 0.44791667 | C29: 256 | D29: Plain | E29: 60 | F29: (B) laser sample lower incision (8) | G29: Sample (?) | I29: 1s | J29: 1 | K29: 4 | L29: 442 | M29: IN | N29: 20 | O29: Depth Scan | R29: -2800 | S29: -2244 | T29: 4 | U29: 140 | V29: 21min | W29: 621 | X29: 1600 | Y29: 2436 | AA29: kapton-sample-kapton
A30: 17/12/24 | B30: 0.45833333 | C30: 256 | D30: Plain | E30: 60 | F30: (B) laser sample lower incision (8) | G30: Nothing | I30: 1s | J30: 1 | K30: 4 | L30: 442 | M30: IN | N30: 20 | O30: Depth Scan | R30: -2800 | S30: -2244 | T30: 4 | U30: 140 | V30: 21min | W30: 621 | X30: 1600 | Y30: 2436 | AA30: kapton-blank-kapton
A31: 17/12/24 | B31: 0.46875 | C31: 131 | D31: Plain | E31: 500 | F31: B3 - Bleo 4 - PBSMET (R24 07) | G31: Sample (?) | I31: 1s | J31: 1 | K31: 4 | L31: 442 | M31: IN | N31: 20 | O31: Depth Scan | R31: -2580 | S31: -3200 | T31: 4 | U31: 150 | V31: 25min | W31: 621 | X31: 1600 | Y31: 2436 | AA31: Ultralene-sample-ultralene
A32: 17/12/24 | B32: 0.47916667 | C32: 131 | D32: Plain | E32: 500 | F32: B3 - Bleo 4 - PBSMET (R24 07) | G32: Nothing | I32: 1s | J32: 1 | K32: 4 | L32: 442 | M32: IN | N32: 20 | O32: Depth Scan | R32: -2580 | S32: -3200 | T32: 4 | U32: 150 | V32: 25min | W32: 621 | X32: 1600 | Y32: 2436 | AA32: Ultralene-blank-ultralene
A33: 17/12/24 | B33: 0.48958333 | C33: 131 | D33: Plain | E33: 500 | F33: B3 - Bleo 4 - PBSMET (R24 07) | G33: Sample (?) | I33: 1s | J33: 1 | K33: 4 | L33: 442 | M33: IN | N33: 20 | O33: Depth Scan | R33: -2580 | S33: -3200 | T33: 4 | U33: 150 | V33: 25min | W33: 621 | X33: 1600 | Y33: 2436 | AA33: Ultralene-sample-ultralene
A34: 29/01/25 | B34: 0.60416667 | D34: Plain | E34: 12 | I34: 1s | J34: 1 | K34: 10 | L34: 442 | M34: OUT | N34: 20 | O34: line scan | Z34: line scan1
A35: 29/01/25 | B35: 0.60416667 | D35: Plain | E35: 12 | I35: 1s | J35: 1 | K35: 10 | L35: 442 | M35: OUT | N35: 20 | O35: line scan | Z35: line scan 1 extended
A36: 29/01/25 | B36: 0.60416667 | D36: Plain | E36: 12 | I36: 1s | J36: 1 | K36: 10 | L36: 442 | M36: OUT | N36: 20 | O36: Grid Scan | Z36: grid lower dermis
A37: 29/01/25 | B37: 0.60416667 | D37: Plain | E37: 12 | I37: 1s | J37: 1 | K37: 10 | L37: 442 | M37: OUT | N37: 20 | O37: Grid Scan | Z37: grid lower dermis extended
A38: 29/01/25 | B38: 0.60416667 | D38: Plain | E38: 12 | I38: 1s | J38: 1 | K38: 10 | L38: 442 | M38: OUT | N38: 20 | O38: Grid Scan | Z38: grid upper dermis
A39: 29/01/25 | B39: 0.60416667 | D39: Plain | E39: 12 | I39: 1s | J39: 1 | K39: 10 | L39: 442 | M39: OUT | N39: 20 | O39: Grid Scan | Z39: grid upper dermis extended
A40: 29/01/25 | B40: 0.60416667 | D40: Plain | E40: 12 | I40: 1s | J40: 1 | K40: 10 | L40: 442 | M40: OUT | N40: 20 | O40: Grid Scan | Z40: d10 outside WB grid
...

Sheet SAXS Master Manifest
A1: Scan No. | B1: End No. | C1: Date | D1: Type | E1: Subtype | F1: Eppendorf | G1: X-number | H1: Y-number | I1: no points | J1: IQRED | K1: ICHI RED | L1: IQFIT | M1: ICHIFIT | N1: Heatmap | O1: Good | P1: REDUCTION | Q1: FITTING | R1: HEATMAP | S1: REDUCTION | T1: FITTING | U1: HEATMAP
A2: 692797 | C2: 45861 | D2: Day 10 | E2: Wound | F2: 104 | G2: 101 | H2: 56 | I2: =G2*H2 -> 5656 | J2: Y | K2: Y | L2: Y | M2: Y | N2: Y | O2: Y | P2: =($S$2/$T$3) -> 0.91959799 | Q2: =($T$2/$T$3) -> 0.86934673 | R2: =($U$2/$T$3) -> 0.53266332 | S2: =COUNTIF(K2:K200, "<>") -> 183 | T2: =COUNTIF(M2:M200, "<>") -> 173 | U2: =COUNTIF(N2:N200, "<>") -> 106
A3: 692822 | C3: 45861 | D3: Day 10 | E3: Wound | F3: 107 | G3: 98 | H3: 68 | I3: 6664 | J3: Y | K3: Y | L3: Y | M3: Y | N3: Y | O3: Y | P3: =($S$2/$T$3) -> 0.91959799 | Q3: =($T$2/$T$3) -> 0.86934673 | R3: =($U$2/$T$3) -> 0.53266332 | T3: =COUNTIF(A2:A200, "<>") -> 199
A4: 692824 | C4: 45861 | D4: Day 10 | E4: Wound | F4: 106 | G4: 105 | H4: 63 | I4: 6615 | J4: Y | K4: Y | L4: Y | M4: Y | N4: Y | O4: Y | P4: =($S$2/$T$3) -> 0.91959799 | Q4: =($T$2/$T$3) -> 0.86934673 | R4: =($U$2/$T$3) -> 0.53266332
A5: 753760 | C5: 45801 | D5: T5224 Day 10 | E5: AP1 | F5: 302 | G5: 59 | H5: 155 | I5: 9157 | J5: Y | K5: Y | L5: Y | M5: Y | N5: Y | O5: no wound | P5: =($S$2/$T$3) -> 0.91959799 | Q5: =($T$2/$T$3) -> 0.86934673 | R5: =($U$2/$T$3) -> 0.53266332
A6: 753764 | C6: 45801 | D6: Vehicle Day 10 | E6: AP1 | F6: 303 | G6: 37 | H6: 19 | I6: 725 | J6: Y | K6: Y | L6: Y | M6: Y | N6: Y | O6: no wound | P6: =($S$2/$T$3) -> 0.91959799 | Q6: =($T$2/$T$3) -> 0.86934673 | R6: =($U$2/$T$3) -> 0.53266332
A7: 753766 | C7: 45801 | D7: Vehicle Day 10 | E7: AP1 | F7: 303 | G7: 71 | H7: 57 | I7: 4058 | J7: Y | K7: Y | L7: Y | M7: Y | N7: Y | O7: spot over wound? | P7: =($S$2/$T$3) -> 0.91959799 | Q7: =($T$2/$T$3) -> 0.86934673 | R7: =($U$2/$T$3) -> 0.53266332
A8: 753767 | C8: 45801 | D8: T5224 Day 10 | E8: AP1 | F8: 304 | G8: 77 | H8: 71 | I8: 5457 | J8: Y | K8: Y | L8: Y | M8: Y | N8: Y | O8: no wound | P8: =($S$2/$T$3) -> 0.91959799 | Q8: =($T$2/$T$3) -> 0.86934673 | R8: =($U$2/$T$3) -> 0.53266332
A9: 753768 | C9: 45801 | D9: T5224 Day 10 | E9: AP1 | F9: 306 | G9: 74 | H9: 57 | I9: 4243 | J9: Y | K9: Y | L9: Y | M9: Y | N9: Y | O9: Y | P9: =($S$2/$T$3) -> 0.91959799 | Q9: =($T$2/$T$3) -> 0.86934673 | R9: =($U$2/$T$3) -> 0.53266332
A10: 753775 | C10: 45801 | D10: Vehicle Day 10 | E10: AP1 | F10: 307 | G10: 94 | H10: 57 | I10: 5365 | J10: Y | K10: Y | L10: Y | M10: Y | N10: Y | O10: no wound | P10: =($S$2/$T$3) -> 0.91959799 | Q10: =($T$2/$T$3) -> 0.86934673 | R10: =($U$2/$T$3) -> 0.53266332
A11: 753774 | C11: 45801 | D11: Vehicle Day 10 | E11: AP1 | F11: 309 | G11: 59 | H11: 55 | I11: 3208 | J11: Y | K11: Y | L11: Y | M11: Y | N11: Y | O11: Y | P11: =($S$2/$T$3) -> 0.91959799 | Q11: =($T$2/$T$3) -> 0.86934673 | R11: =($U$2/$T$3) -> 0.53266332
A12: 753770 | C12: 45801 | D12: Vehicle Day 10 | E12: AP1 | F12: 310 | G12: 51 | H12: 70 | I12: 3541 | J12: Y | K12: Y | L12: Y | M12: Y | N12: Y | O12: Y | P12: =($S$2/$T$3) -> 0.91959799 | Q12: =($T$2/$T$3) -> 0.86934673 | R12: =($U$2/$T$3) -> 0.53266332
A13: 753771 | C13: 45801 | D13: Vehicle Day 10 | E13: AP1 | F13: 310 | G13: 20 | H13: 28 | I13: 567 | J13: Y | K13: Y | L13: Y | M13: Y | N13: Y | O13: no wound | P13: =($S$2/$T$3) -> 0.91959799 | Q13: =($T$2/$T$3) -> 0.86934673 | R13: =($U$2/$T$3) -> 0.53266332
A14: 753772 | C14: 45801 | D14: Vehicle Day 10 | E14: AP1 | F14: 310 | G14: 20 | H14: 28 | I14: 567 | J14: Y | K14: Y | L14: Y | M14: Y | N14: Y | O14: no wound | P14: =($S$2/$T$3) -> 0.91959799 | Q14: =($T$2/$T$3) -> 0.86934673 | R14: =($U$2/$T$3) -> 0.53266332
A15: 753773 | C15: 45801 | D15: Vehicle Day 10 | E15: AP1 | F15: 310 | G15: 51 | H15: 17 | I15: 859 | J15: Y | K15: Y | L15: Y | M15: Y | N15: Y | O15: no wound | P15: =($S$2/$T$3) -> 0.91959799 | Q15: =($T$2/$T$3) -> 0.86934673 | R15: =($U$2/$T$3) -> 0.53266332
... A22: 692823 | C22: 45861 | D22: Day 14 | E22: Wound | F22: 97 | G22: 71 | H22: 86 | I22: 6106 | J22: Y | K22: Y | L22: Y | M22: Y | N22: Y | O22: Y | P22: =($S$2/$T$3) -> 0.91959799 | Q22: =($T$2/$T$3) -> 0.86934673 | R22: =($U$2/$T$3) -> 0.53266332
A23: 692834 | C23: 45861 | D23: Day 14 | E23: Wound | F23: 96 | G23: 101 | H23: 55 | I23: =G23*H23 -> 5555 | J23: Y | K23: Y | L23: Y | M23: Y | N23: Y | P23: =($S$2/$T$3) -> 0.91959799 | Q23: =($T$2/$T$3) -> 0.86934673 | R23: =($U$2/$T$3) -> 0.53266332
A24: 725637 | B24: ? | C24: 46014 | D24: Day 14 | E24: Wound | F24: 157 | G24: 60 | H24: 105 | I24: 6300 | N24: Y | O24: no end point | P24: =($S$2/$T$3) -> 0.91959799 | Q24: =($T$2/$T$3) -> 0.86934673 | R24: =($U$2/$T$3) -> 0.53266332
A25: 753780 | C25: 45801 | D25: Day 14 | E25: Wound | F25: 322 | G25: 23 | H25: 15 | I25: =G25*H25 -> 345 | J25: Y | K25: Y | L25: Y | M25: Y | N25: Y | O25: no sample | P25: =($S$2/$T$3) -> 0.91959799 | Q25: =($T$2/$T$3) -> 0.86934673 | R25: =($U$2/$T$3) -> 0.53266332
A26: 753781 | C26: 45801 | D26: Day 14 | E26: Wound | F26: 322 | G26: 63 | H26: 124 | I26: 7738 | J26: Y | K26: Y | L26: Y | M26: Y | N26: Y | O26: wonky | P26: =($S$2/$T$3) -> 0.91959799 | Q26: =($T$2/$T$3) -> 0.86934673 | R26: =($U$2/$T$3) -> 0.53266332
A27: 753782 | C27: 45801 | D27: Day 14 | E27: Wound | F27: 98 SAXS | G27: 30 | H27: 33 | I27: 985 | J27: Y | K27: Y | L27: Y | M27: Y | N27: Y | O27: no sample | P27: =($S$2/$T$3) -> 0.91959799 | Q27: =($T$2/$T$3) -> 0.86934673 | R27: =($U$2/$T$3) -> 0.53266332
A28: 753783 | C28: 45801 | D28: Day 14 | E28: Wound | F28: 98 SAXS | G28: 63 | H28: 140 | I28: 8750 | J28: Y | K28: Y | L28: Y | M28: Y | N28: Y | O28: Y | P28: =($S$2/$T$3) -> 0.91959799 | Q28: =($T$2/$T$3) -> 0.86934673 | R28: =($U$2/$T$3) -> 0.53266332
A29: 725396 | B29: 725488 | C29: 46014 | D29: Day 21 | E29: Wound | F29: 163 | G29: 55 | H29: 92.5 | I29: 5087.5 | J29: Y | K29: Y | M29: Y | N29: Y | O29: not sure where wound is | P29: =($S$2/$T$3) -> 0.91959799 | Q29: =($T$2/$T$3) -> 0.86934673 | R29: =($U$2/$T$3) -> 0.53266332
A30: 725493 | B30: 725582 | C30: 46014 | D30: Day 21 | E30: Wound | F30: 168 | G30: 40 | H30: 90 | I30: 3600 | J30: Y | K30: Y | M30: Y | N30: Y | O30: not sure where wound is | P30: =($S$2/$T$3) -> 0.91959799 | Q30: =($T$2/$T$3) -> 0.86934673 | R30: =($U$2/$T$3) -> 0.53266332
A31: 725586 | B31: 725695 | C31: 46014 | D31: Day 21 | E31: Wound | F31: 169 | G31: 78 | H31: 110 | I31: 8580 | J31: Y | K31: Y | M31: Y | N31: Y | O31: not sure where wound is | P31: =($S$2/$T$3) -> 0.91959799 | Q31: =($T$2/$T$3) -> 0.86934673 | R31: =($U$2/$T$3) -> 0.53266332
A32: 725696 | B32: 725785 | C32: 46014 | D32: Day 21 | E32: Wound | F32: 171 | G32: 95 | H32: 90 | I32: 8550 | J32: Y | K32: Y | L32: Y | M32: Y | N32: Y | O32: Y | P32: =($S$2/$T$3) -> 0.91959799 | Q32: =($T$2/$T$3) -> 0.86934673 | R32: =($U$2/$T$3) -> 0.53266332
A33: 753793 | C33: 45801 | D33: Day 21 | E33: Wound | F33: 165(15) SAXS-2 | G33: 49 | H33: 161 | I33: 7877 | J33: Y | K33: Y | L33: Y | M33: Y | N33: Y | O33: Y | P33: =($S$2/$T$3) -> 0.91959799 | Q33: =($T$2/$T$3) -> 0.86934673 | R33: =($U$2/$T$3) -> 0.53266332
A34: 753798 | C34: 45801 | D34: Day 21 | E34: Wound | F34: 170(20) SAXS-2 | G34: 50 | H34: 165 | I34: 8244 | J34: Y | K34: Y | L34: Y | M34: Y | N34: Y | O34: Y | P34: =($S$2/$T$3) -> 0.91959799 | Q34: =($T$2/$T$3) -> 0.86934673 | R34: =($U$2/$T$3) -> 0.53266332
A35: 692795 | C35: 45861 | D35: Day 4 | E35: Wound | F35: 74 | G35: 146 | H35: 76 | I35: =G35*H35 -> 11096 | J35: Y | K35: Y | L35: Y | M35: Y | N35: Y | O35: Y | P35: =($S$2/$T$3) -> 0.91959799 | Q35: =($T$2/$T$3) -> 0.86934673 | R35: =($U$2/$T$3) -> 0.53266332
A36: 692799 | C36: 45861 | D36: Day 4 | E36: Wound | F36: 61 | G36: 101 | H36: 88 | I36: 8888 | J36: Y | K36: Y | L36: Y | M36: Y | N36: Y | O36: Y | P36: =($S$2/$T$3) -> 0.91959799 | Q36: =($T$2/$T$3) -> 0.86934673 | R36: =($U$2/$T$3) -> 0.53266332
A37: 692826 | C37: 45861 | D37: Day 4 | E37: Wound | F37: 66 | G37: 83 | H37: 69 | I37: 5727 | J37: Y | K37: Y | L37: Y | M37: Y | N37: Y | O37: Y | P37: =($S$2/$T$3) -> 0.91959799 | Q37: =($T$2/$T$3) -> 0.86934673 | R37: =($U$2/$T$3) -> 0.53266332
A38: 753757 | C38: 45801 | D38: Day 4 | E38: Wound | F38: 62 SAXS | G38: 63 | H38: 59 | I38: 3736 | J38: Y | K38: Y | L38: Y | M38: Y | N38: Y | O38: not sure where wound is -- But might be ok as a control? | P38: =($S$2/$T$3) -> 0.91959799 | Q38: =($T$2/$T$3) -> 0.86934673 | R38: =($U$2/$T$3) -> 0.53266332
A39: 753758 | C39: 45801 | D39: Day 4 | E39: Wound | F39: 67 SAXS | G39: 70 | H39: 73 | I39: 5067 | J39: Y | K39: Y | L39: Y | M39: Y | N39: Y | P39: =($S$2/$T$3) -> 0.91959799 | Q39: =($T$2/$T$3) -> 0.86934673 | R39: =($U$2/$T$3) -> 0.53266332
A40: 753759 | C40: 45801 | D40: Day 4 | E40: Wound | F40: 75 SAXS | G40: 53 | H40: 71 | I40: 3750 | J40: Y | K40: Y | L40: Y | M40: Y | N40: Y | P40: =($S$2/$T$3) -> 0.91959799 | Q40: =($T$2/$T$3) -> 0.86934673 | R40: =($U$2/$T$3) -> 0.53266332
A41: 753776 | C41: 45801 | D41: Day 4 | E41: Wound | F41: 312 | G41: 37 | H41: 22 | I41: =G41*H41 -> 814 | J41: Y | K41: Y | L41: Y | M41: Y | N41: Y | O41: no sample | P41: =($S$2/$T$3) -> 0.91959799 | Q41: =($T$2/$T$3) -> 0.86934673 | R41: =($U$2/$T$3) -> 0.53266332
A42: 753777 | C42: 45801 | D42: Day 4 | E42: Wound | F42: 312 | G42: 59 | H42: 70 | I42: 4168 | J42: Y | K42: Y | L42: Y | M42: Y | N42: Y | O42: not sure where wound is | P42: =($S$2/$T$3) -> 0.91959799 | Q42: =($T$2/$T$3) -> 0.86934673 | R42: =($U$2/$T$3) -> 0.53266332
A43: 692781 | C43: 45861 | D43: PN2 | E43: Aging | F43: 1 | G43: 95 | H43: 51 | I43: 4845 | J43: Y | K43: Y | L43: Y | M43: Y | P43: =($S$2/$T$3) -> 0.91959799 | Q43: =($T$2/$T$3) -> 0.86934673 | R43: =($U$2/$T$3) -> 0.53266332
A44: 692782 | C44: 45861 | D44: E16.5 | E44: Aging | F44: 11 | G44: 68 | H44: 81 | I44: 5508 | J44: Y | K44: Y | L44: Y | M44: Y | P44: =($S$2/$T$3) -> 0.91959799 | Q44: =($T$2/$T$3) -> 0.86934673 | R44: =($U$2/$T$3) -> 0.53266332
A45: 692836 | C45: 45861 | D45: E16.5 | E45: Aging | F45: 13 | G45: 79 | H45: 55 | I45: 4345 | J45: Y | K45: Y | L45: Y | M45: Y | P45: =($S$2/$T$3) -> 0.91959799 | Q45: =($T$2/$T$3) -> 0.86934673 | R45: =($U$2/$T$3) -> 0.53266332
A46: 692783 | C46: 45861 | D46: E18.5 | E46: Aging | F46: 30 | G46: 179 | H46: 68 | I46: 12172 | J46: Y | K46: Y | L46: Y | M46: Y | P46: =($S$2/$T$3) -> 0.91959799 | Q46: =($T$2/$T$3) -> 0.86934673 | R46: =($U$2/$T$3) -> 0.53266332
...

Sheet Sheet1
A1: TYPE | L1: Completed | M1: Images | N1: Cut | O1: Analysed | W1: Completed | X1: Images | Y1: Cut | Z1: Analysed
A2: Paper | Q2: Paper
A8: Wounding | Q8: Wounding
A9: Control 60um | B9: 1 | C9: 6 | D9: 18 | E9: 30 | F9: 44 | G9: 4 | H9: 5 | I9: 20 | J9: 32 | K9: 45 | N9: yes | O9: yes | Q9: Control 60um | R9: 1 | S9: 6 | T9: 17 | U9: 29 | V9: 32
A10: Control 12um | B10: 12 | C10: 28 | D10: 41 | E10: 53 | F10: 54 | Q10: Control 12um
A11: D4 | Q11: D4
A12: D7 | B12: 230 | C12: 233 | D12: 25 | E12: 26 | F12: 23 | G12: 35 | H12: 357 | I12: 359 | N12: yes | O12: yes | Q12: D7 | R12: 230 | S12: 238 | T12: 357 | U12: 359
A13: D10 | B13: 210 | C13: 212 | D13: 215 | Q13: D10 | R13: 212
A14: D14 | B14: 156 | C14: 166 | D14: 244 | E14: 242 | F14: 355 | G14: 356 | N14: yes | O14: yes | Q14: D14 | R14: 157 | S14: 242 | T14: 355 | U14: 356
A15: D21 | Q15: D21
A17: AP1 | Q17: AP1
A18: TS | B18: 269 | C18: 274 | D18: 272 | E18: 271 | F18: 273 | G18: 300 | H18: 301 | N18: yes | O18: yes | Q18: TS | R18: 269 | S18: 271 | T18: 273
A19: VH | B19: 270 | C19: 275 | D19: 277 | E19: 23 | F19: 20 | G19: 201 | H19: 302 | I19: 303 | N19: yes | O19: yes | Q19: VH | R19: 270 | S19: 275 | T19: 277 | U19: 302
A20: CL | B20: 278 | C20: 284 | D20: 285 | E20: 281 | F20: 282 | G20: 294 | H20: 295 | N20: yes | O20: yes | Q20: CL | R20: 278 | S20: 285 | T20: 281 | U20: 282
A21: AC | B21: 279 | C21: 280 | D21: 289 | E21: 286 | F21: 298 | G21: 297 | N21: yes | O21: yes | Q21: AC | R21: 279 | S21: 280 | T21: 289 | U21: 286
A23: Bleomycin | Q23: Bleomycin
A24: PBS | B24: 308 | C24: 305 | D24: 309 | E24: 310 | F24: 341 | G24: 342 | Q24: PBS | R24: 308 | S24: 305 | T24: 342
A25: 2W | B25: 306 | C25: 311 | D25: 312 | E25: 326 | F25: 324 | Q25: 2W | R25: 306 | S25: 311 | T25: 326 | U25: 324
A26: 4W 3R | B26: 307 | C26: 313 | D26: 304 | Q26: 4W 3R | R26: 307
A27: 4W 5R | B27: 322 | C27: 321 | D27: 320 | E27: 323 | F27: 332 | Q27: 4W 5R | R27: 322 | S27: 321 | T27: 320 | U27: 323
A28: PBS MET | B28: 336 | C28: 337 | D28: 338 | H28: 9153.1 | Q28: PBS MET | R28: 336 | S28: 337
A29: BM | B29: 331 | C29: 329 | D29: 330 | E29: 334 | F29: 333 | H29: 9111.6 | Q29: BM | R29: 329 | S29: 330 | T29: 334 | U29: 333
A30: 4W MET | B30: 325 | C30: 327 | D30: 328 | E30: 335 | H30: 1909.9 | Q30: 4W MET | R30: 327 | S30: 328
A31: PBS OKN | B31: 319 | C31: 339 | D31: 340 | H31: 2644.7 | Q31: PBS OKN | R31: 319 | S31: 339 | T31: 340
A32: 4W OKN | B32: 318 | C32: 316 | D32: 314 | E32: 315 | F32: 317 | Q32: 4W OKN | R32: 318 | S32: 314 | T32: 315 | U32: 317
A34: JEB | Q34: JEB
A35: WT | B35: 382 | C35: 376 | Q35: WT
A36: KO | B36: 379 | C36: 387 | D36: 386 | E36: 390 | F36: 393 | Q36: KO
A37: WT D7 | B37: 552 | C37: 553 | Q37: WT D7
A38: KO D7 | B38: 561 | C38: 562 | D38: 541 | E38: 546 | Q38: KO D7
A39: WT D10 | B39: 472 | C39: 475 | D39: 487 | Q39: WT D10
A40: KO D10 | B40: 478 | C40: 490 | D40: 484 | E40: 482 | Q40: KO D10
A41: WT D14 | B41: 632 | C41: 629 | D41: 623 | E41: 642 | Q41: WT D14 | R41: 632
A42: KO D14 | B42: 626 | C42: 636 | D42: 644 | E42: 647 | Q42: KO D14
A43: WT D19 | B43: 535 | C43: 539 | Q43: WT D19
A44: KO D19 | B44: 517 | C44: 523 | D44: 526 | E44: 529 | Q44: KO D19
A45: WT VH | B45: 572 | C45: 576 | D45: 595 | Q45: WT VH
A46: KO VH | B46: 580 | Q46: KO VH
A47: WT RAD | Q47: WT RAD
A48: KO RAD | Q48: KO RAD
...

Sheet by TECHNIQUE (done)
A1: NUMBER | B1: RAMAN | D1: NI | F1: labSAXS | H1: SAXS | J1: TYPE | K1: Sub type | L1: NI | M1: SAXS | O1: NI | Q1: Group | R1: Date | S1: Tip size | T1: Tip stiffness | U1: indentation depth | V1: approach speed | W1: hold time
B2: Sample Label | C2: Description | D2: Sample Label | E2: Description | F2: Sample Label | G2: Description | H2: Sample Label | I2: Description | O2: Sample Label | P2: Description
A3: 1 | E3: Control 6 | F3: 173 | G3: =MANIFEST!G337 -> PBS | J3: Wounding | K3: Control | L3: 5 | M3: 7 | O3: 23 H | P3: Unwounded | Q3: Control | R3: 14/08/23 | S3: 26 | T3: 0.49 | U3: 5000 | V3: 2s | W3: 3s
A4: 2 | E4: Control 7 | F4: 120 | G4: =MANIFEST!G293 -> 4W | K4: 4 | L4: 0 | M4: 7 | O4: 25 I | P4: Day 7 | Q4: Wounding | R4: 29/08/23 | S4: 26.5 | T4: 0.48 | U4: 5000 | V4: 2s | W4: 3s
A5: 3 | D5: 1 | E5: Control 1 | F5: 172 | G5: =MANIFEST!G336 -> PBS | K5: 7 | L5: 2 | M5: 9 | O5: 26 I | P5: Day 7 | Q5: Wounding | R5: 21/08/23 | S5: 26.5 | T5: 0.48 | U5: 5000 | V5: 2s | W5: 3s
A6: 4 | D6: 6 | E6: Control 2 | F6: 142 | G6: =MANIFEST!G313 -> 4W | K6: 10 | L6: 3 | M6: 3 | O6: 35 L | P6: Unwounded | Q6: Control | R6: 23/08/23 | S6: 26.5 | T6: 0.48 | U6: 5000 | V6: 2s | W6: 3s
A7: 5 | D7: 18 | E7: Control 3 | F7: 68 | G7: =MANIFEST!G241 -> Day 4 | K7: 14 | L7: 4 | M7: 4 | O7: 156 AG | P7: Day 14 | Q7: Wounding | R7: 13/02/24 | S7: 26 | T7: 0.51 | U7: 5000 | V7: 2s | W7: 3s
A8: 6 | D8: 30 | E8: Control 4 | F8: 76 | G8: =MANIFEST!G249 -> Day 4 | K8: 21 | L8: 0 | M8: 4 | O8: 166 AI | P8: Day 14 | Q8: Wounding | R8: 29/05/24 | S8: 27.5 | T8: 0.49 | U8: 5000 | V8: 2s | W8: 3s
A9: 7 | D9: 44 | E9: Control 5 | F9: 129 | G9: =MANIFEST!G301 -> PBSMET | J9: AP1 | K9: Control | L9: 4 | M9: 5 | O9: 16 F | P9: T5224 Day 10 | Q9: AP1 | R9: 14/03/24 | S9: 26 | T9: 0.51 | U9: 1250 | V9: 1s | W9: 1s
A10: 8 | K10: T5224 | L10: 6 | M10: 5 | O10: 19 G | P10: T5224 Day 10 | Q10: AP1 | R10: 45632 | S10: 27.5 | T10: 0.49 | U10: 1250 | V10: 1s | W10: 3s
A11: 9 | D11: 25I | E11: Day 7 | J11: CL | K11: Control | L11: 4 | M11: 0 | O11: 20 H | P11: Vehicle Day 10 | Q11: AP1 | R11: 14/03/24 | S11: 26 | T11: 0.51 | U11: 5000 | V11: 1 | W11: 1
A12: 10 | D12: 35L | E12: Day 7 | K12: Clomipramine | L12: 6 | M12: 0 | O12: 23 H | P12: Vehicle Day 10 | Q12: AP1 | R12: 21/03/24 | S12: 27.5 | T12: 0.49 | U12: 1250 | V12: 1s | W12: 3s
A13: 11 | D13: 26I | E13: Day 7 | J13: Bleomycin | K13: PBS | L13: 0 | M13: 3 | O13: 201 | P13: Vehicle Day 10 | Q13: AP1 | R13: 29/05/24 | S13: 27.5 | T13: 0.49 | U13: 1250 | V13: 1.786 | W13: 3s
A14: 12 | D14: 233 | E14: Day 7 | K14: 2w | L14: 0 | M14: 3 | O14: 210 | P14: Day 10 | Q14: Wounding | R14: 20/06/24 | S14: 27.5 | T14: 0.49 | U14: 5000 | V14: 2 | W14: 3s
A15: 13 | D15: 230 | E15: Day 7 | K15: 4w | L15: 0 | M15: 5 | O15: 212 | P15: Day 10 | Q15: Wounding | R15: 20/06/24 | S15: 27.5 | T15: 0.49 | U15: 5000 | V15: 2 | W15: 3s
A16: 14 | K16: PBSMET | L16: 0 | M16: 3 | O16: 215 | P16: Day 10 | Q16: Wounding | R16: 25/06/24 | S16: 27.5 | T16: 0.49 | U16: 5000 | V16: 2 | W16: 3s
A17: 15 | D17: 210 | E17: Day 10 | K17: BMMET | L17: 0 | M17: 3 | O17: 230 | P17: Day 7 | Q17: Wounding | R17: 25/06/24 | S17: 27.5 | T17: 0.49 | U17: 5000 | V17: 2 | W17: 3s
A18: 16 | D18: 212 | E18: Day 10 | J18: JEB | K18: Control | L18: 0 | M18: 0 | O18: 242 | P18: Day 14 | Q18: Wounding | R18: 45329 | S18: 27.5 | T18: 0.49 | U18: 5000 | V18: 2 | W18: 3s
A19: 17 | D19: 215 | E19: Day 10 | K19: Mild | L19: 0 | M19: 0 | O19: 220 | P19: Day 21 | Q19: Wounding | R19: 45329 | S19: 27.5 | T19: 0.49 | U19: 5000 | V19: 2 | W19: 3s
A20: 18 | K20: Med | L20: 0 | M20: 0
A21: 19 | D21: 244 | E21: Day 14 | K21: Sev | L21: 0 | M21: 0
A22: 20 | D22: 166 | E22: Day 14 | K22: Sev+d4 | L22: 0 | M22: 0
A23: 21 | D23: 156 | E23: Day 14 | K23: Sev+d7 | L23: 0 | M23: 0
A24: 22 | D24: 242 | E24: Day 14 | K24: Sev+d10 | L24: 0 | M24: 0
A25: 23 | K25: Sev+d14 | L25: 0 | M25: 0
A26: 24 | D26: 225 | E26: Day 21 | K26: Sev+d21 | L26: 0 | M26: 0
A27: 25 | D27: 220 | E27: Day 21 | K27: RecLamn | L27: 0 | M27: 0
A28: 26 | J28: Keloid | K28: Control | L28: 0 | M28: 0
A29: 27 | D29: 19G f32 | E29: T5224 Day 10 | K29: Middle | L29: 0 | M29: 0
A30: 28 | D30: 273 f31 | E30: T5224 Day 10 | K30: Edge | L30: 0 | M30: 0
A31: 29 | D31: 269 f11 | E31: T5224 Day 10 | J31: Aging | K31: E16.5 | M31: 2
A32: 30 | D32: 274 f22 | E32: T5224 Day 10 | K32: E18.5 | M32: 1
A33: 31 | D33: 272 f32 | E33: T5224 Day 10 | K33: P0 | M33: 1
A34: 32 | D34: 300 | E34: T5224 Day 10 | K34: P2 | M34: 1
A35: 33 | D35: 301 m11 | E35: T5224 Day 10 | K35: P4 | M35: 1
A36: 34 | K36: P10 | M36: 1
A37: 35 | D37: 16F f21 | E37: Vehicle Day 10
A38: 36 | D38: 20 f11 | E38: Vehicle Day 10
A39: 37 | D39: 23 f22 | E39: Vehicle Day 10
A40: 38 | D40: 270 | E40: Vehicle Day 10
...

Sheet SAXS Done
A1: SAMPLE NUMBER | B1: DLS NUMBER | C1: Label | D1: Size | E1: end? | F1: TYPE | G1: DATE | H1: EXP NUMBER | I1: DAWN | J1: I(q) | K1: CSV | L1: I(X) | N1: SCALED AREA NON PARAM | O1: TOTAL AREA ARR | P1: SCALED AREA | Q1: DPERIOD | R1: CSV master
A2: 62 SAXS | B2: 753757 | C2: sample 62 scan 3 | D2: 60x64 | F2: Day 4 | G2: 45436 | H2: SM36684-1 | I2: Yes | J2: Yes
A3: 67 SAXS | B3: 753758 | C3: sample 67 | D3: 73x70 | F3: Day 4 | G3: 45436 | H3: SM36684-1 | I3: Yes | J3: Yes
A4: 75 SAXS | B4: 753759 | C4: sample 75 | D4: 72x53 | F4: Day 4 | G4: 45436 | H4: SM36684-1 | I4: Yes | J4: Yes
A5: 302 | B5: 753760 | C5: Sample 302 | D5: 155x60 | F5: T5224 Day 10 | G5: 45436 | H5: SM36684-1 | I5: Yes | J5: Yes
A6: 303 | B6: 753766 | C6: sample 303 | D6: 57x72 | F6: Vehicle Day 10 | G6: 45436 | H6: SM36684-1 | I6: Yes | J6: Yes
A7: 304 | B7: 753767 | C7: sample 304 | D7: 72x77 | F7: T5224 Day 10 | G7: 45436 | H7: SM36684-1 | I7: Yes | J7: Yes
A8: 306 | B8: 753768 | C8: sample 306 | D8: 57x75 | F8: T5224 Day 10 | G8: 45436 | H8: SM36684-1 | I8: Yes | J8: Yes
A9: 307 | B9: 753775 | C9: sample 307 | D9: 58x94 | F9: Vehicle Day 10 | G9: 45436 | H9: SM36684-1 | I9: Yes | J9: Yes
A10: 309 | B10: 753774 | C10: sample 309 | D10: 55x59 | F10: Vehicle Day 10 | G10: 45436 | H10: SM36684-1 | I10: Yes | J10: Yes
A11: 310 | B11: 753770 | C11: sample 310 | D11: 71x51 | F11: Vehicle Day 10 | G11: 45436 | H11: SM36684-1 | I11: Yes | J11: Yes
A12: 301 | B12: 753786 | C12: sample 301b | D12: 74x86 | F12: T5224 Day 10 | G12: 45436 | H12: SM36684-1 | I12: Yes | J12: Yes
A13: 301 | B13: 753785 | C13: sample 301a | D13: 171x86 | H13: SM36684-1 | I13: Yes
A14: 308 | B14: 753769 | C14: sample 308 | D14: 77x47 | F14: Vehicle Day 10 | G14: 45436 | H14: SM36684-1 | I14: Yes
A15: 312 | B15: 753777 | C15: sample 312 | D15: 71x60 | F15: Day 4 | G15: 45436 | H15: SM36684-1 | I15: Yes
A16: 320 | B16: 753788 | C16: sample 320 | D16: 131x63 | F16: Day 7 | G16: 45436 | H16: SM36684-1 | I16: Yes
A17: 322 | B17: 753781 | C17: sample 322 | D17: 124x63 | F17: Day 14 | G17: 45436 | H17: SM36684-1 | I17: Yes
A18: 98 SAXS | B18: 753783 | C18: sample 98 | D18: 141x63 | F18: Day 14 | G18: 45436 | H18: SM36684-1 | I18: Yes
A19: 152(2) SAXS-2 | B19: 753790 | C19: sample 152 | D19: 141x63 | F19: Day 7 | G19: 45436 | H19: SM36684-1 | I19: Yes
A20: 305 | B20: 753831 | C20: sample 305 | D20: 136x96 | F20: T5224 Day 10 | G20: 45436 | H20: SM36684-1 | I20: Yes
A21: 153(3) SAXS-2 | B21: 753792 | C21: sample 153 | D21: 161x50 | F21: Day 7 | G21: 45436 | H21: SM36684-1 | I21: Yes
A22: 165(15) SAXS-2 | B22: 753793 | C22: sample 165 | D22: 161x50 | F22: Day 21 | G22: 45436 | H22: SM36684-1 | I22: Yes
A23: 311 | B23: 753795 | C23: sample 311 | D23: 115x75 | F23: Day 4 | G23: 45436 | H23: SM36684-1 | I23: Yes
A24: 319 | B24: 753797 | C24: sample 319 | D24: 81x106 | F24: Day 7 | G24: 45436 | H24: SM36684-1 | I24: Yes
A25: 79 SAXS | B25: 753830 | C25: sample 79 | D25: 146x57 | F25: Unwounded | G25: 45436 | H25: SM36684-1 | I25: Yes
A26: 71 SAXS | B26: 753828 | C26: sample 71 bottomhalf real sample | D26: 109x58 | F26: Unwounded | G26: 45436 | H26: SM36684-1 | I26: Yes
A27: 78 SAXS | B27: 753829 | C27: sample 78 | D27: 146x52 | F27: Unwounded | G27: 45436 | H27: SM36684-1 | I27: Yes
A28: 61 | B28: 692799 | F28: B1 - Wound day 4 | G28: 45496 | H28: SM33398-1
A29: 64 | B29: 692820 | F29: B1 – outside wound bed | G29: 45496 | H29: SM33398-1
A30: 66 | B30: 692826 | F30: B2 - Wound day 4 | G30: 45496 | H30: SM33398-1
A31: 69 | B31: 692821 | F31: B2 – outside wound bed | G31: 45496 | H31: SM33398-1
A32: 73 | B32: 692762 | F32: B2 – outside wound bed | G32: 45496 | H32: SM33398-1
A33: 74 | B33: 692795 | F33: B3 - Wound day 4 | G33: 45496 | H33: SM33398-1
A34: 80 | B34: 692796 | F34: B1 - Wound day 7 | G34: 45496 | H34: SM33398-1
A35: 83 | B35: 692800 | F35: B2 - Wound day 7 | G35: 45496 | H35: SM33398-1
A36: 90 | B36: 692827 | F36: B4 - Wound day 7 | G36: 45496 | H36: SM33398-1
A37: 96 | B37: 692834 | F37: B2 - Wound day 14 | G37: 45496 | H37: SM33398-1
A38: 97 | B38: 692823 | F38: B2 - Wound day 14 | G38: 45496 | H38: SM33398-1
A39: 100 | B39: 692798 | F39: B3 - Wound day 14 | G39: 45496 | H39: SM33398-1
... A57: 141 | B57: 692778 | F57: B2 – Bleo 3R - 4w (4) | G57: 45496 | H57: SM33398-1
...

Sheet by SAMPLE (all)
A1: NUMBER | B1: WOUNDING | D1: AGING | F1: BLEOMYCIN | H1: DIGESTED | J1: VEHICLE | L1: PLAIN | N1: AP1 | P1: JEB | R1: LASER | U1: WOUNDING | W1: AGING | Y1: BLEOMYCIN | AA1: DIGESTED | AC1: VEHICLE | AE1: PLAIN | AG1: AP1 | AI1: JEB | AK1: LASER
B2: Sample Label | C2: Description | D2: Sample Label | E2: Description | F2: Sample Label | G2: Description | H2: Sample Label | I2: Description | J2: Sample Label | K2: Description | L2: Sample Label | M2: Description | N2: Sample Label | O2: Description | P2: Sample Label | Q2: Description | R2: Sample Label | S2: Description | T2: Number | U2: Sample Label | V2: Description | W2: Sample Label | X2: Description | Y2: Sample Label | Z2: Description | AA2: Sample Label | AB2: Description | AC2: Sample Label | AD2: Description | AE2: Sample Label | AF2: Description | AG2: Sample Label | AH2: Description | AI2: Sample Label | AJ2: Description | AK2: Sample Label | AL2: Description
A3: 1 | B3: {=_xlfn._xlws.FILTER(MANIFEST!A:A, ISNUMBER(SEARCH("wounding", MANIFEST!E:E)), "No results")} -> 16 F PW 7 | C3: {=_xlfn._xlws.FILTER(MANIFEST!G:G, ISNUMBER(SEARCH("wounding", MANIFEST!E:E)), "No results")} -> Day 7 | D3: {=_xlfn._xlws.FILTER(MANIFEST!A:A, ISNUMBER(SEARCH("aging", MANIFEST!E:E)), "No results")} -> 40 N | E3: {=_xlfn._xlws.FILTER(MANIFEST!G:G, ISNUMBER(SEARCH("aging", MANIFEST!E:E)), "No results")} -> E16.5 | F3: {=_xlfn._xlws.FILTER(MANIFEST!A:A, ISNUMBER(SEARCH("bleomycin", MANIFEST!E:E)), "No results")} -> 46 P | G3: {=_xlfn._xlws.FILTER(MANIFEST!G:G, ISNUMBER(SEARCH("bleomycin", MANIFEST!E:E)), "No results")} -> 2W | H3: {=_xlfn._xlws.FILTER(MANIFEST!A:A, ISNUMBER(SEARCH("digestion", MANIFEST!E:E)), "No results")} -> 1 A - Undigested | I3: {=_xlfn._xlws.FILTER(MANIFEST!G:G, ISNUMBER(SEARCH("digestion", MANIFEST!E:E)), "No results")} -> 14 days digested | J3: {=_xlfn._xlws.FILTER(MANIFEST!A:A, ISNUMBER(SEARCH("vehicle", MANIFEST!E:E)), "No results")} -> No results | K3: {=_xlfn._xlws.FILTER(MANIFEST!G:G, ISNUMBER(SEARCH("vehicle", MANIFEST!E:E)), "No results")} -> No results | L3: {=_xlfn._xlws.FILTER(MANIFEST!A:A, ISNUMBER(SEARCH("plain", MANIFEST!E:E)), "No results")} -> 1 Paper | M3: {=_xlfn._xlws.FILTER(MANIFEST!G:G, ISNUMBER(SEARCH("plain", MANIFEST!E:E)), "No results")} -> Plain | N3: {=_xlfn._xlws.FILTER(MANIFEST!A:A, ISNUMBER(SEARCH("AP1", MANIFEST!E:E)), "No results")} -> 16 F ap1 | O3: {=_xlfn._xlws.FILTER(MANIFEST!G:G, ISNUMBER(SEARCH("AP1", MANIFEST!E:E)), "No results")} -> T5224 Day 10 | P3: {=_xlfn._xlws.FILTER(MANIFEST!A:A, ISNUMBER(SEARCH("JEB", MANIFEST!E:E)), "No results")} -> 375B | Q3: {=_xlfn._xlws.FILTER(MANIFEST!G:G, ISNUMBER(SEARCH("JEB", MANIFEST!E:E)), "No results")} -> JEB | R3: {=_xlfn._xlws.FILTER(MANIFEST!A:A, ISNUMBER(SEARCH("LASER", MANIFEST!E:E)), "No results")} -> 255 | S3: {=_xlfn._xlws.FILTER(MANIFEST!G:G, ISNUMBER(SEARCH("LASER", MANIFEST!E:E)), "No results")} -> Incision | T3: 1 | U3: {=_xlfn._xlws.FILTER(MANIFEST!T:T, ISNUMBER(SEARCH("wounding", MANIFEST!X:X)), "No results")} -> No results | V3: {=_xlfn._xlws.FILTER(MANIFEST!Y:Y, ISNUMBER(SEARCH("wounding", MANIFEST!X:X)), "No results")} -> No results | W3: {=_xlfn._xlws.FILTER(MANIFEST!T:T, ISNUMBER(SEARCH("aging", MANIFEST!X:X)), "No results")} -> No results | X3: {=_xlfn._xlws.FILTER(MANIFEST!Y:Y, ISNUMBER(SEARCH("aging", MANIFEST!X:X)), "No results")} -> No results | Y3: {=_xlfn._xlws.FILTER(MANIFEST!T:T, ISNUMBER(SEARCH("bleomycin", MANIFEST!X:X)), "No results")} -> No results | Z3: {=_xlfn._xlws.FILTER(MANIFEST!Y:Y, ISNUMBER(SEARCH("bleomycin", MANIFEST!X:X)), "No results")} -> No results | AA3: {=_xlfn._xlws.FILTER(MANIFEST!T:T, ISNUMBER(SEARCH("digestion", MANIFEST!X:X)), "No results")} -> No results | AB3: {=_xlfn._xlws.FILTER(MANIFEST!Y:Y, ISNUMBER(SEARCH("digestion", MANIFEST!X:X)), "No results")} -> No results | AC3: {=_xlfn._xlws.FILTER(MANIFEST!T:T, ISNUMBER(SEARCH("vehicle", MANIFEST!X:X)), "No results")} -> No results | AD3: {=_xlfn._xlws.FILTER(MANIFEST!Y:Y, ISNUMBER(SEARCH("vehicle", MANIFEST!X:X)), "No results")} -> No results | AE3: {=_xlfn._xlws.FILTER(MANIFEST!T:T, ISNUMBER(SEARCH("plain", MANIFEST!X:X)), "No results")} -> No results | AF3: {=_xlfn._xlws.FILTER(MANIFEST!Y:Y, ISNUMBER(SEARCH("plain", MANIFEST!X:X)), "No results")} -> No results | AG3: {=_xlfn._xlws.FILTER(MANIFEST!T:T, ISNUMBER(SEARCH("AP1", MANIFEST!X:X)), "No results")} -> No results | AH3: {=_xlfn._xlws.FILTER(MANIFEST!Y:Y, ISNUMBER(SEARCH("AP1", MANIFEST!X:X)), "No results")} -> No results | AI3: {=_xlfn._xlws.FILTER(MANIFEST!T:T, ISNUMBER(SEARCH("JEB", MANIFEST!X:X)), "No results")} -> No results | AJ3: {=_xlfn._xlws.FILTER(MANIFEST!Y:Y, ISNUMBER(SEARCH("JEB", MANIFEST!X:X)), "No results")} -> No results | AK3: {=_xlfn._xlws.FILTER(MANIFEST!W:W, ISNUMBER(SEARCH("JEB", MANIFEST!AA:AA)), "No results")} -> No results | AL3: {=_xlfn._xlws.FILTER(MANIFEST!AB:AB, ISNUMBER(SEARCH("JEB", MANIFEST!AA:AA)), "No results")} -> No results
A4: 2 | B4: 17 F PW 7 | C4: Day 7 | D4: 41 N | E4: E16.5 | F4: 47 P | G4: 2W | H4: 2 A - Undigested | I4: 14 days digested | L4: 2 Paper | M4: Plain | N4: 17 F ap1 | O4: T5224 Day 10 | P4: 376 | Q4: JEB | R4: 256 | S4: Incision | T4: 2
A5: 3 | B5: 18 F PW 7 | C5: Day 7 | D5: 42 N | E5: E16.5 | F5: 48 P | G5: 2W | H5: 3 A - Undigested | I5: 14 days digested | L5: 3 Paper | M5: Plain | N5: 18 G ap1 | O5: T5224 Day 10 | P5: 377 | Q5: JEB | R5: 257 | S5: Incision | T5: 3
A6: 4 | B6: S1 SAXS 1 | C6: Day 7 | D6: 43 O | E6: E16.5 | F6: 49 Q | G6: 2W | H6: 4 B - Undigested | I6: 21 days digested | L6: 4 Paper | M6: Plain | N6: 19 G ap1 | O6: T5224 Day 10 | P6: 378 | Q6: JEB | R6: 258 | S6: Incision | T6: 4
A7: 5 | B7: S2 SAXS 2 | C7: Day 7 | D7: 44 O | E7: E16.5 | F7: 50 Q | G7: 2W | H7: 5 B - Undigested | I7: 21 days digested | L7: 5 Paper | M7: Plain | N7: 20 H ap1 | O7: Vehicle Day 10 | P7: 379 | Q7: JEB | R7: 259 | S7: Incision | T7: 5
A8: 6 | B8: S3 SAXS 3 | C8: Day 7 | D8: 45 O | E8: E16.5 | F8: 51 R | G8: 2W | H8: 6 B - Undigested | I8: 21 days digested | L8: 6 Paper | M8: Plain | N8: 21 H ap1 | O8: Vehicle Day 10 | P8: 380 | Q8: JEB | R8: 260 | S8: Incision | T8: 6
A9: 7 | B9: S4 SAXS 4 | C9: Unwounded | D9: 66 W | E9: E16.5 | F9: 52 R | G9: 2W | H9: 7 C - Digested | I9: 24hr digested | L9: 7 Paper | M9: Plain | N9: 22 H ap1 | O9: Vehicle Day 10 | P9: 381 | Q9: JEB | R9: 261 | S9: Incision | T9: 7
A10: 8 | B10: S5 SAXS 5 | C10: Unwounded | D10: 67 W | E10: E16.5 | F10: 53 R | G10: 2W | H10: 8 C - Digested | I10: 24hr digested | L10: 8 Paper | M10: Plain | N10: 23 H ap1 | O10: Vehicle Day 10 | P10: 382 | Q10: JEB | R10: 262 | S10: Incision | T10: 8
A11: 9 | B11: S6 SAXS 6 | C11: Unwounded | D11: 68 W | E11: E16.5 | F11: 54 S | G11: 4W | H11: 9 C - Digested | I11: 24hr digested | L11: 9 Paper | M11: Plain | N11: 301 | O11: T5224 Day 10 | P11: 383 | Q11: JEB | R11: 263 | S11: Incision | T11: 9
A12: 10 | B12: S7 SAXS 7 | C12: Unwounded | D12: 69 X | E12: PN10 | F12: 55 S | G12: 4W | H12: 10 D - Digested | I12: 48hr digested | L12: 10 Paper | M12: Plain | N12: 302 | O12: T5224 Day 10 | P12: 384 | Q12: JEB | R12: 264 | S12: Incision | T12: 10
A13: 11 | B13: S8 SAXS 8 | C13: Unwounded | D13: 70 X | E13: PN10 | F13: 56 S | G13: 4W | H13: 11 D - Digested | I13: 48hr digested | L13: 11 Paper | M13: Plain | N13: 303 | O13: Vehicle Day 10 | P13: 385 | Q13: JEB | R13: 265 | S13: Incision | T13: 11
A14: 12 | B14: 19 G | C14: Unwounded | D14: 71 X | E14: PN10 | F14: 57 T | G14: 4W | H14: 12 D - Digested | I14: 48hr digested | L14: 12 Paper | M14: Plain | N14: 304 | O14: T5224 Day 10 | P14: 386 | Q14: JEB | R14: 266 | S14: Incision | T14: 12
A15: 13 | B15: 20 G | C15: Unwounded | D15: 72 Y | E15: PN10 | F15: 58 T | G15: 4W | H15: 13 E - Digested | I15: 48hr digested | L15: 13 Paper | M15: Plain | N15: 305 | O15: T5224 Day 10 | P15: 387 | Q15: JEB | R15: 267 | S15: Incision | T15: 13
A16: 14 | B16: 21 G | C16: Unwounded | D16: 73 Y | E16: PN10 | F16: 59 T | G16: 4W | H16: 14 E - Digested | I16: 48hr digested | L16: 14 Paper | M16: Plain | N16: 306 | O16: T5224 Day 10 | P16: 388 | Q16: JEB | R16: 268 | S16: Incision | T16: 14
A17: 15 | B17: 22 H | C17: Unwounded | D17: 74 Y | E17: PN10 | F17: 60 U | G17: PBS | H17: 15 E - Digested | I17: 48hr digested | L17: 15 Paper | M17: Plain | N17: 307 | O17: Vehicle Day 10 | P17: 389 | Q17: JEB | R17: 1H | S17: Incision | T17: 15
A18: 16 | B18: 23 H | C18: Unwounded | D18: P2 1 | E18: PN2 | F18: 61 U | G18: PBS | L18: 16 Paper | M18: Plain | N18: 308 | O18: Vehicle Day 10 | P18: 390 | Q18: JEB | R18: 2H | S18: Incision | T18: 16
A19: 17 | B19: 24 H | C19: Unwounded | D19: E18.5 | E19: E18.5 | F19: 62 U | G19: PBS | L19: 17 Paper | M19: Plain | N19: 309 | O19: Vehicle Day 10 | P19: 391 | Q19: JEB | R19: 3H | S19: Incision | T19: 17
A20: 18 | B20: 25 I | C20: Day 7 | D20: 1 SAXS | E20: PN2 | F20: 63 V | G20: PBS | L20: 18 Paper | M20: Plain | N20: 310 | O20: Vehicle Day 10 | P20: 392 | Q20: JEB | R20: 4H | S20: Incision | T20: 18
A21: 19 | B21: 26 I | C21: Day 7 | D21: 2 SAXS | E21: PN2 | F21: 64 V | G21: PBS | L21: 19 Paper | M21: Plain | N21: 200 | O21: T5224 Day 10 | P21: 393 | Q21: JEB | R21: 5H | S21: Incision | T21: 19
A22: 20 | B22: 27 I | C22: Day 7 | D22: 3 SAXS | E22: PN2 | F22: 65 V | G22: PBS | L22: 20 Paper | M22: Plain | N22: 201 | O22: Vehicle Day 10 | P22: 394 | Q22: JEB | R22: 6H | S22: Incision | T22: 20
